, "create_all")
flask_web  |   File "/usr/local/lib/python3.9/site-packages/flask_sqlalchemy/extension.py", line 881, in _call_for_binds
flask_web  |     getattr(metadata, op_name)(bind=engine)
flask_web  |   File "/usr/local/lib/python3.9/site-packages/sqlalchemy/sql/schema.py", line 5925, in create_all
flask_web  |     bind._run_ddl_visitor(
flask_web  |   File "/usr/local/lib/python3.9/site-packages/sqlalchemy/engine/base.py", line 3248, in _run_ddl_visitor
flask_web  |     with self.begin() as conn:
flask_web  |   File "/usr/local/lib/python3.9/contextlib.py", line 119, in __enter__
flask_web  |     return next(self.gen)
flask_web  |   File "/usr/local/lib/python3.9/site-packages/sqlalchemy/engine/base.py", line 3238, in begin
flask_web  |     with self.connect() as conn:
flask_web  |   File "/usr/local/lib/python3.9/site-packages/sqlalchemy/engine/base.py", line 3274, in connect
flask_web  |     return self._connection_cls(self)
flask_web  |   File "/usr/local/lib/python3.9/site-packages/sqlalchemy/engine/base.py", line 148, in __init__
flask_web  |     Connection._handle_dbapi_exception_noconnection(
flask_web  |   File "/usr/local/lib/python3.9/site-packages/sqlalchemy/engine/base.py", line 2439, in _handle_dbapi_exception_noconnection
flask_web  |     raise sqlalchemy_exception.with_traceback(exc_info[2]) from e
flask_web  |   File "/usr/local/lib/python3.9/site-packages/sqlalchemy/engine/base.py", line 146, in __init__
flask_web  |     self._dbapi_connection = engine.raw_connection()
flask_web  |   File "/usr/local/lib/python3.9/site-packages/sqlalchemy/engine/base.py", line 3298, in raw_connection
flask_web  |     return self.pool.connect()
flask_web  |   File "/usr/local/lib/python3.9/site-packages/sqlalchemy/pool/base.py", line 449, in connect
flask_web  |     return _ConnectionFairy._checkout(self)
flask_web  |   File "/usr/local/lib/python3.9/site-packages/sqlalchemy/pool/base.py", line 1264, in _checkout
flask_web  |     fairy = _ConnectionRecord.checkout(pool)
flask_web  |   File "/usr/local/lib/python3.9/site-packages/sqlalchemy/pool/base.py", line 713, in checkout
flask_web  |     rec = pool._do_get()
flask_web  |   File "/usr/local/lib/python3.9/site-packages/sqlalchemy/pool/impl.py", line 180, in _do_get
flask_web  |     self._dec_overflow()
flask_web  |   File "/usr/local/lib/python3.9/site-packages/sqlalchemy/util/langhelpers.py", line 146, in __exit__
flask_web  |     raise exc_value.with_traceback(exc_tb)
flask_web  |   File "/usr/local/lib/python3.9/site-packages/sqlalchemy/pool/impl.py", line 177, in _do_get
flask_web  |     return self._create_connection()
flask_web  |   File "/usr/local/lib/python3.9/site-packages/sqlalchemy/pool/base.py", line 390, in _create_connection
flask_web  |     return _ConnectionRecord(self)
flask_web  |   File "/usr/local/lib/python3.9/site-packages/sqlalchemy/pool/base.py", line 675, in __init__
flask_web  |     self.__connect()
flask_web  |   File "/usr/local/lib/python3.9/site-packages/sqlalchemy/pool/base.py", line 902, in __connect
flask_web  |     pool.logger.debug("Error on connect(): %s", e)
flask_web  |   File "/usr/local/lib/python3.9/site-packages/sqlalchemy/util/langhelpers.py", line 146, in __exit__
flask_web  |     raise exc_value.with_traceback(exc_tb)
flask_web  |   File "/usr/local/lib/python3.9/site-packages/sqlalchemy/pool/base.py", line 897, in __connect
flask_web  |     self.dbapi_connection = connection = pool._invoke_creator(self)
flask_web  |   File "/usr/local/lib/python3.9/site-packages/sqlalchemy/engine/create.py", line 646, in connect
flask_web  |     return dialect.connect(*cargs, **cparams)
flask_web  |   File "/usr/local/lib/python3.9/site-packages/sqlalchemy/engine/default.py", line 625, in connect
flask_web  |     return self.loaded_dbapi.connect(*cargs, **cparams)  # type: ignore[no-any-return]  # NOQA: E501
flask_web  |   File "/usr/local/lib/python3.9/site-packages/psycopg2/__init__.py", line 122, in connect
flask_web  |     conn = _connect(dsn, connection_factory=connection_factory, **kwasync)
flask_web  | sqlalchemy.exc.OperationalError: (psycopg2.OperationalError) connection to server at "db" (172.18.0.2), port 5432 failed: FATAL:  database "boekhoud" does not exist
flask_web  |
flask_web  | (Background on this error at: https://sqlalche.me/e/20/e3q8)
flask_web  | [2025-04-06 19:17:42 +0000] [22] [INFO] Worker exiting (pid: 22)
flask_web  | 2025-04-06 19:17:42,503 - app - INFO - Logs monitoring system geregistreerd
flask_web  | 2025-04-06 19:17:42,505 - app - INFO - Onboarding tutorial system geregistreerd
flask_web  | [2025-04-06 19:17:42 +0000] [19] [ERROR] Exception in worker process
flask_web  | Traceback (most recent call last):
flask_web  |   File "/usr/local/lib/python3.9/site-packages/sqlalchemy/engine/base.py", line 146, in __init__
flask_web  |     self._dbapi_connection = engine.raw_connection()
flask_web  |   File "/usr/local/lib/python3.9/site-packages/sqlalchemy/engine/base.py", line 3298, in raw_connection
flask_web  |     return self.pool.connect()
flask_web  |   File "/usr/local/lib/python3.9/site-packages/sqlalchemy/pool/base.py", line 449, in connect
flask_web  |     return _ConnectionFairy._checkout(self)
flask_web  |   File "/usr/local/lib/python3.9/site-packages/sqlalchemy/pool/base.py", line 1264, in _checkout
flask_web  |     fairy = _ConnectionRecord.checkout(pool)
flask_web  |   File "/usr/local/lib/python3.9/site-packages/sqlalchemy/pool/base.py", line 713, in checkout
flask_web  |     rec = pool._do_get()
flask_web  |   File "/usr/local/lib/python3.9/site-packages/sqlalchemy/pool/impl.py", line 180, in _do_get
flask_web  |     self._dec_overflow()
flask_web  |   File "/usr/local/lib/python3.9/site-packages/sqlalchemy/util/langhelpers.py", line 146, in __exit__
flask_web  |     raise exc_value.with_traceback(exc_tb)
flask_web  |   File "/usr/local/lib/python3.9/site-packages/sqlalchemy/pool/impl.py", line 177, in _do_get
flask_web  |     return self._create_connection()
flask_web  |   File "/usr/local/lib/python3.9/site-packages/sqlalchemy/pool/base.py", line 390, in _create_connection
flask_web  |     return _ConnectionRecord(self)
flask_web  |   File "/usr/local/lib/python3.9/site-packages/sqlalchemy/pool/base.py", line 675, in __init__
flask_web  |     self.__connect()
flask_web  |   File "/usr/local/lib/python3.9/site-packages/sqlalchemy/pool/base.py", line 902, in __connect
flask_web  |     pool.logger.debug("Error on connect(): %s", e)
flask_web  |   File "/usr/local/lib/python3.9/site-packages/sqlalchemy/util/langhelpers.py", line 146, in __exit__
flask_web  |     raise exc_value.with_traceback(exc_tb)
flask_web  |   File "/usr/local/lib/python3.9/site-packages/sqlalchemy/pool/base.py", line 897, in __connect
flask_web  |     self.dbapi_connection = connection = pool._invoke_creator(self)
flask_web  |   File "/usr/local/lib/python3.9/site-packages/sqlalchemy/engine/create.py", line 646, in connect
flask_web  |     return dialect.connect(*cargs, **cparams)
flask_web  |   File "/usr/local/lib/python3.9/site-packages/sqlalchemy/engine/default.py", line 625, in connect
flask_web  |     return self.loaded_dbapi.connect(*cargs, **cparams)  # type: ignore[no-any-return]  # NOQA: E501
flask_web  |   File "/usr/local/lib/python3.9/site-packages/psycopg2/__init__.py", line 122, in connect
flask_web  |     conn = _connect(dsn, connection_factory=connection_factory, **kwasync)
flask_web  | psycopg2.OperationalError: connection to server at "db" (172.18.0.2), port 5432 failed: FATAL:  database "boekhoud" does not exist
flask_web  |
flask_web  |
flask_web  | The above exception was the direct cause of the following exception:
flask_web  |
flask_web  | Traceback (most recent call last):
flask_web  |   File "/usr/local/lib/python3.9/site-packages/gunicorn/arbiter.py", line 608, in spawn_worker
flask_web  |     worker.init_process()
flask_web  |   File "/usr/local/lib/python3.9/site-packages/gunicorn/workers/base.py", line 135, in init_process
flask_web  |     self.load_wsgi()
flask_web  |   File "/usr/local/lib/python3.9/site-packages/gunicorn/workers/base.py", line 147, in load_wsgi
flask_web  |     self.wsgi = self.app.wsgi()
flask_web  |   File "/usr/local/lib/python3.9/site-packages/gunicorn/app/base.py", line 66, in wsgi
flask_web  |     self.callable = self.load()
flask_web  |   File "/usr/local/lib/python3.9/site-packages/gunicorn/app/wsgiapp.py", line 57, in load
flask_web  |     return self.load_wsgiapp()
flask_web  |   File "/usr/local/lib/python3.9/site-packages/gunicorn/app/wsgiapp.py", line 47, in load_wsgiapp
flask_web  |     return util.import_app(self.app_uri)
flask_web  |   File "/usr/local/lib/python3.9/site-packages/gunicorn/util.py", line 370, in import_app
flask_web  |     mod = importlib.import_module(module)
flask_web  |   File "/usr/local/lib/python3.9/importlib/__init__.py", line 127, in import_module
flask_web  |     return _bootstrap._gcd_import(name[level:], package, level)
flask_web  |   File "<frozen importlib._bootstrap>", line 1030, in _gcd_import
flask_web  |   File "<frozen importlib._bootstrap>", line 1007, in _find_and_load
flask_web  |   File "<frozen importlib._bootstrap>", line 986, in _find_and_load_unlocked
flask_web  |   File "<frozen importlib._bootstrap>", line 680, in _load_unlocked
flask_web  |   File "<frozen importlib._bootstrap_external>", line 850, in exec_module
flask_web  |   File "<frozen importlib._bootstrap>", line 228, in _call_with_frames_removed
flask_web  |   File "/app/main.py", line 11, in <module>
flask_web  |     initialize_app()
flask_web  |   File "/app/app.py", line 244, in initialize_app
flask_web  |     db.create_all()
flask_web  |   File "/usr/local/lib/python3.9/site-packages/flask_sqlalchemy/extension.py", line 900, in create_all
flask_web  |     self._call_for_binds(bind_key, "create_all")
flask_web  |   File "/usr/local/lib/python3.9/site-packages/flask_sqlalchemy/extension.py", line 881, in _call_for_binds
flask_web  |     getattr(metadata, op_name)(bind=engine)
flask_web  |   File "/usr/local/lib/python3.9/site-packages/sqlalchemy/sql/schema.py", line 5925, in create_all
flask_web  |     bind._run_ddl_visitor(
flask_web  |   File "/usr/local/lib/python3.9/site-packages/sqlalchemy/engine/base.py", line 3248, in _run_ddl_visitor
flask_web  |     with self.begin() as conn:
flask_web  |   File "/usr/local/lib/python3.9/contextlib.py", line 119, in __enter__
flask_web  |     return next(self.gen)
flask_web  |   File "/usr/local/lib/python3.9/site-packages/sqlalchemy/engine/base.py", line 3238, in begin
flask_web  |     with self.connect() as conn:
flask_web  |   File "/usr/local/lib/python3.9/site-packages/sqlalchemy/engine/base.py", line 3274, in connect
flask_web  |     return self._connection_cls(self)
flask_web  |   File "/usr/local/lib/python3.9/site-packages/sqlalchemy/engine/base.py", line 148, in __init__
flask_web  |     Connection._handle_dbapi_exception_noconnection(
flask_web  |   File "/usr/local/lib/python3.9/site-packages/sqlalchemy/engine/base.py", line 2439, in _handle_dbapi_exception_noconnection
flask_web  |     raise sqlalchemy_exception.with_traceback(exc_info[2]) from e
flask_web  |   File "/usr/local/lib/python3.9/site-packages/sqlalchemy/engine/base.py", line 146, in __init__
flask_web  |     self._dbapi_connection = engine.raw_connection()
flask_web  |   File "/usr/local/lib/python3.9/site-packages/sqlalchemy/engine/base.py", line 3298, in raw_connection
flask_web  |     return self.pool.connect()
flask_web  |   File "/usr/local/lib/python3.9/site-packages/sqlalchemy/pool/base.py", line 449, in connect
flask_web  |     return _ConnectionFairy._checkout(self)
flask_web  |   File "/usr/local/lib/python3.9/site-packages/sqlalchemy/pool/base.py", line 1264, in _checkout
flask_web  |     fairy = _ConnectionRecord.checkout(pool)
flask_web  |   File "/usr/local/lib/python3.9/site-packages/sqlalchemy/pool/base.py", line 713, in checkout
flask_web  |     rec = pool._do_get()
flask_web  |   File "/usr/local/lib/python3.9/site-packages/sqlalchemy/pool/impl.py", line 180, in _do_get
flask_web  |     self._dec_overflow()
flask_web  |   File "/usr/local/lib/python3.9/site-packages/sqlalchemy/util/langhelpers.py", line 146, in __exit__
flask_web  |     raise exc_value.with_traceback(exc_tb)
flask_web  |   File "/usr/local/lib/python3.9/site-packages/sqlalchemy/pool/impl.py", line 177, in _do_get
flask_web  |     return self._create_connection()
flask_web  |   File "/usr/local/lib/python3.9/site-packages/sqlalchemy/pool/base.py", line 390, in _create_connection
flask_web  |     return _ConnectionRecord(self)
flask_web  |   File "/usr/local/lib/python3.9/site-packages/sqlalchemy/pool/base.py", line 675, in __init__
flask_web  |     self.__connect()
flask_web  |   File "/usr/local/lib/python3.9/site-packages/sqlalchemy/pool/base.py", line 902, in __connect
flask_web  |     pool.logger.debug("Error on connect(): %s", e)
flask_web  |   File "/usr/local/lib/python3.9/site-packages/sqlalchemy/util/langhelpers.py", line 146, in __exit__
flask_web  |     raise exc_value.with_traceback(exc_tb)
flask_web  |   File "/usr/local/lib/python3.9/site-packages/sqlalchemy/pool/base.py", line 897, in __connect
flask_web  |     self.dbapi_connection = connection = pool._invoke_creator(self)
flask_web  |   File "/usr/local/lib/python3.9/site-packages/sqlalchemy/engine/create.py", line 646, in connect
flask_web  |     return dialect.connect(*cargs, **cparams)
flask_web  |   File "/usr/local/lib/python3.9/site-packages/sqlalchemy/engine/default.py", line 625, in connect
flask_web  |     return self.loaded_dbapi.connect(*cargs, **cparams)  # type: ignore[no-any-return]  # NOQA: E501
flask_web  |   File "/usr/local/lib/python3.9/site-packages/psycopg2/__init__.py", line 122, in connect
flask_web  |     conn = _connect(dsn, connection_factory=connection_factory, **kwasync)
flask_web  | sqlalchemy.exc.OperationalError: (psycopg2.OperationalError) connection to server at "db" (172.18.0.2), port 5432 failed: FATAL:  database "boekhoud" does not exist
flask_web  |
flask_web  | (Background on this error at: https://sqlalche.me/e/20/e3q8)
flask_web  | [2025-04-06 19:17:42 +0000] [19] [INFO] Worker exiting (pid: 19)
